<?xml version="1.0" ?>
<robot name="mbot">

  <link name="world" />
  
  <joint name="world_to_base_link" type="fixed">
    <parent link="world" />
    <child link="base_link" />
  </joint>
  
  <link name="base_link" />
  
  <joint name="base_link_to_cart" type="prismatic">
    <parent link="base_link" />
    <child link="cart" />
    <axis xyz="1 0 0" rpy="0 0 0"/>
    <limit effort="100" velocity="1000.0" lower= "-1.5707" upper="1.5707" />
    <joint_properties damping="0.0" friction="0.0"/>
  </joint>
  
  <link name="cart">
    <visual>
      <origin xyz="0 0 0" rpy="0 0 0" />
      <geometry>
        <cylinder length="0.16" radius="0.20"/>
      </geometry>
      <material name="yellow">
        <color rgba="1 0.4 0 1" />
      </material>
    </visual>
    <collision>
      <geometry>
        <cylinder length="0.16" radius="0.20"/>
      </geometry>
    </collision>
    <inertial>
      <mass value="10"/>
      <inertia ixx="1.0" ixy="0.0" ixz="0.0" iyy="1.0" iyz="0.0" izz="1.0"/>
    </inertial>
  </link>
  
  <joint name="pend_joint" type="revolute">
    <origin xyz="0 0 0.08" rpy="0 0 0"/>
    <limit effort="100" velocity="1.0" lower= "-1.5707" upper="1.5707" />
    <parent link="cart"/>
    <child link="pend"/>
    <axis xyz="0 1 0"/>
  </joint>
  
  <link name="pend">
    <visual>
      <origin xyz="0 0 0.6" rpy="0 0 0"/>
      <geometry>
        <cylinder length="1.2" radius="0.02"/>
      </geometry>
      <material name="white">
        <color rgba="1 1 1 0.9"/>
      </material>
    </visual>
    <collision>
      <geometry>
        <cylinder length="1.2" radius="0.02"/>
      </geometry>
    </collision>
    <inertial>
      <mass value="10"/>
      <inertia ixx="0.018" ixy="0.0" ixz="0.0" iyy="0.018" iyz="0.0" izz="0.018"/>
    </inertial>
  </link>
  
</robot>
